Workbook
Name Aerogel_batts_rolls: Material_classif_dropdowns!$B$65
Name Aggregates: Material_classif_dropdowns!$B$44:$B$48
Name Aggregates_general: Material_classif_dropdowns!$C$65:$C$66
Name Aggregates_sand_stones: Material_classif_dropdowns!$B$25:$B$27
Name Aircrete: Material_classif_dropdowns!$D$65:$D$67
Name Aluminum: Material_classif_dropdowns!$E$65
Name Aluminum_frame: Material_classif_dropdowns!$F$65
Name Area: Dropdowns!$V$5:$V$8
Name Asphalt_bitumen: Material_classif_dropdowns!$G$65:$G$67
Name Batts_and_rolls: Material_classif_dropdowns!$C$44:$C$47
Name Beams_and_footings: 'Rules of thumb'!$I$4:$I$9
Name Beams_columns: Material_classif_dropdowns!$H$65
Name Bespoke: Dropdowns!$Q$52:$Q$130
Name Bespoke_match: 'Crossmatch material classific.'!$X$2:$X$491
Name Biomass: Material_classif_dropdowns!$I$65:$I$70
Name Biomass_batts_rolls: Material_classif_dropdowns!$J$65:$J$71
Name Biomass_board: Material_classif_dropdowns!$K$65:$K$66
Name Bituminous_roof_membrane: Material_classif_dropdowns!$L$65:$L$67
Name Blocks_bricks_and_precast_products: Material_classif_dropdowns!$C$25:$C$30
Name Board: Material_classif_dropdowns!$D$44:$D$46
Name Boards: Material_classif_dropdowns!$M$65:$M$77
Name BoM_element: 'Bill of material'!$F$6:$F$2003
Name BoM_layer: 'Bill of material'!$G$6:$G$2003
Name BoM_material: 'Bill of material'!$Y$6:$Y$2003
Name BoM_material_summary: 'Bill of material'!$AF$6:$AF$2003
Name BoM_vertical: 'Bill of material'!$E$6:$E$2003
Name BoM_volume: 'Bill of material'!$AE$6:$AE$2003
Name BoM_weight: 'Bill of material'!$AC$6:$AC$2003
Name Breather_membrane: Material_classif_dropdowns!$N$65:$N$66
Name BUD_MI_L4_match: 'Crossmatch material classific.'!$D$2:$D$491
Name building_layer: Dropdowns!$D$5:$D$7
Name building_use: Dropdowns!$S$5:$S$22
Name C_class: Material_classif_dropdowns!$O$65:$O$76
Name Calcium_Silicate_Sheets: Material_classif_dropdowns!$P$65
Name Carbon_steel_door: Material_classif_dropdowns!$Q$65
Name Ceiling: Material_classif_dropdowns!$E$44:$E$47
Name Cementitious_foam: Material_classif_dropdowns!$R$65
Name Cementitious_mixtures: Material_classif_dropdowns!$F$44:$F$47
Name Ceramics_tiles: Material_classif_dropdowns!$S$65:$S$66
Name Clay: Material_classif_dropdowns!$T$65:$T$66
Name Clay_brick: Material_classif_dropdowns!$U$65:$U$68
Name Clay_concrete_LECA: Material_classif_dropdowns!$V$65:$V$66
Name Clay_concrete_LECA_hollow: Material_classif_dropdowns!$W$65:$W$66
Name Columns_and_piles: 'Rules of thumb'!$I$10:$I$14
Name Concrete: Material_classif_dropdowns!$X$65:$X$67
Name Concrete_aggregate: Material_classif_dropdowns!$Y$65:$Y$67
Name Concrete_brick: Material_classif_dropdowns!$Z$65:$Z$66
Name Concrete_in_situ: Material_classif_dropdowns!$G$44:$G$45
Name Concrete_in_situ_general: Material_classif_dropdowns!$AA$65
Name context: Dropdowns!$F$5:$F$8
Name Copper: Material_classif_dropdowns!$AB$65
Name Countries: Dropdowns!$A$52:$C$300
Name Country: Dropdowns!$A$52:$A$300
Name Coverings_claddings_finishings: Material_classif_dropdowns!$D$25:$D$29
Name Crushed_aggregate: Material_classif_dropdowns!$AC$65:$AC$75
Name D_class: Material_classif_dropdowns!$AD$65:$AD$78
Name Damp_proofing: Material_classif_dropdowns!$AE$65:$AE$66
Name data_collection: Dropdowns!$E$5:$E$10
Name Database_seed_L2_match: 'Crossmatch material classific.'!$K$2:$K$491
Name Database_seed_L3_match: 'Crossmatch material classific.'!$L$2:$L$491

Sheet Readme
C3: BUD-MI Bottom-Up Data: Material Intensity
C4: This template aims to assist with the data collection of buildings' material intensity for bottom-up material stocks and flows analysis and associated research (e.g., embodied carbon, circularity potential, and more).
C5: To make full use of this template, please consult the following additional resources:
C6: (1) The scientific article "BUD-MI: a template that optimizes material intensity data collection and utilization" that describes the development and design of BUD-MI;
C7: (2) The BUD-MI repository on Github (see link below) that includes the newest version (and older ones) of BUD-MI, the User Guide, a tutorial video, and an example of a filled template. Updated versions of BUD-MI will be uploaded to the Github repository. The Github repository allows users to download the latest version of BUD-MI, suggest improvements, and track updates over time.
C8: (3) The Zenodo repository, which also includes the User Guide, the tutorial video, a pre-print of the abovementionned scientific article, and a link to the Github repository.
C10: BUD-MI template
C11: Developed by: | D11: Maud Lanau
C12: Version: | D12: 1.0.0
C13: Date: | D13: 13th May 2025
C14: Excel version: | D14: Microsoft® Excel® for Microsoft 365 MSO (Version 2406 Build 16.0.17726.20078) 64-bit
C15: Acknowledgements: | D15: Thank you to Martin Franssen Christiansson, Pak Yin Lee, David Sindelar, Helena Krantz, Danielle Abbey, Aaron Qiyu Liu, and Taz Lodder for their valuable feedback that improved both the relevance and the usability of BUD-MI. Thank you to all co-authors of the scientific publication (see below) for valuable discussions, insights, inputs, and for sharing relevant resources that contributed to this template.
C17: Scientific Publication
C18: Title: | D18: BUD-MI: a template that optimizes material intensity data collection and utilization.
C19: Authors: | D19: Lanau M*, Gillott C, Mikhelsen W, Zamora K, Berrill P, Heeren N, Schiller G, Mao R, Arora M, Gruhler K, Tanikawa H, Liu G, Densley Tingley D.
C20: Authors' affiliations: | D20: *ML: Department of Architecture and Civil Engineering, Chalmers University of Technology, Gothenburg, Sweden CG, WM, DDT: Department of Civil and Structural Engineering, The University of Sheffield, Sheffield, United Kingdom GL: College of Urban and Environmental Sciences, Peking University, Beijing 100871, China GS: Leibniz Institute of Ecological Urban and Regional Development, Dresden, Germany HT: Graduate School of Environmental Studies, Nagoya University, Japan KZ: Construction Management Department, College of Architecture and the Built Environment, Thomas Jefferson University, Philadelphia, PA, US MA: Net Zero Centre, Department of Engineering, King's College London, United Kingdom NH: City of Zurich, Environmental Construction Group, Switzerland PB: Institute of Environmental Sciences (CML), Leiden University, The Netherlands RM: Department of Environmental and Resource Engineering, Technical University of Denmark, 2800 Lyngby, Denmark WM: WSP UK Limited, United Kingdom
C21: Journal: | D21: TBC
C22: Year: | D22: 2025
C23: DOI: | D23: 10.5281/zenodo.12722009
C24: Link: | D24: https://doi.org/10.5281/zenodo.12722009
C25: Reference: | D25: Lanau, M., Gillott, C., Mihkelson, W., Zamora, K., Berrill, P., Heeren, N., Schiller, G., Mao, R., Arora, M., Gruhler, K., Liu, G., Tanikawa, H., & Densley Tingley, D. (2025). BUD-MI: a template that optimizes material intensity data collection, calculation, and utilization. Zenodo. https://doi.org/10.5281/zenodo.12722010
C27: Repositories
C28: Github Repository | D28: https://zenodo.org/communities/budmi
C29: Zenodo Repository | D29: https://zenodo.org/communities/budmi
C30: Preprint DOI | D30: https://doi.org/10.5281/zenodo.12722009
C32: Terms of Use
C33: The following terms of use for BUD-MI must be abided by: (1) BUD-MI may be used freely in any research projects, as long as the full reference is provided (see 'Reference format' above). (2) The disclaimer below shall be adhered to.
C35: Disclaimer
C36: (1) While diligent efforts have been made to ensure the accuracy of the information contained in BUD-MI, its content remains subject to modification and the authors and affiliated organisations cannot assure its accuracy nor its currency. The right to alter the information without prior notice is reserved. (2) The information contained in BUD-MI is provided without any representation or warranty as to accuracy, currency, quality or fitness for purpose of any kind. While diligently compiled and processed to the best knowledge and ability of the authors, any information contained in BUD-MI should be independently verified before relying on it. Calculations involve assumptions which may affect result certainty. Users should acknowledge the limitations of the data and consider potential consequences of using the data for their specific purpose. The authors and their institutions cannot accept any liability for loss or damage, incurred costs or other results or consequences which may occur as a result of using BUD-MI. (3) Furthermore, BUD-MI provides links to other tools or resources for the convenience of users. The inclusion of these links does not imply endorsement or responsibility for the content, accuracy, or functionality of the linked tools. Users acknowledge that they access these links at their own risk and discretion. The authors of BUD-MI cannot accept any liability for loss or damage, incured costs or other results or consequences which may occur as a results of using the linked tools or resources. (4) The authors of BUD-MI shall not be held responsible for any damages, losses, or consequences arising from the use of BUD-MI and its information, including but not limited to financial loss, business interruption, or any indirect, incidental, or consequential damages. Users are advised to exercise caution and discretion when interpreting and utilizing the data for decision-making purposes. (5) The use of BUD-MI is at the user's own risk, and the authors disclaim any warranties, express or implied, regarding the accuracy, reliability, or suitability of the tool for any particular purpose. By using BUD-MI, users agree to hold harmless the authors and their affiliated organization from any claims, liabilities, or damages arising from such use.

Sheet Content
D3: TABLE OF CONTENT | H3: GOOD TO KNOW
D4: Readme | H4: • Protection and password
D5: Content and Good-to-know | H5: The spreadsheet is protected to avoid mistakenly changing formulas.
D6: Data input | H6: However, there is no password: the protection can easily be removed if needed (e.g., to change the template).
D7: Building Information | H7: To remove the protection, go to: Review > Unprotect Sheet
D8: Scope & Data
D9: Bill of Material | H9: • Help/hint text
D10: Mini tools | H10: Where the annotation ⍰ appears, more information is available as a pop-up and/or in the User Guide.
D11: Search materials
D12: Rules of thumb | H12: • Color coding in the template
D13: Results | H13: Yellow | I13: Searchable dropdown lists.
D14: Result summary | I14: Search and select the most relevant option.
D15: Settings for bespoke MI format | H15: Grey | I15: Automatic calculation.
D16: Bespoke MI format - results | I16: Overriding the formula may impact the functionalities of BUD-MI.
D17: Results - Open MI DB | H17: White or | I17: Manual entry field.
D18: Background data | H18: Light blue | I18: Manually insert relevant value or comment.
D19: Dropdowns
D20: Material_classif_dropdowns
D21: Densities
D22: Crossmatch material classific.
D23: References

Sheet Building information
D3: BUILDING: GENERAL INFORMATION
D4: Fill in the fields below to the extent possible. Fields in marine blue are mandatory.
C6: ⍰ | D6: • Building location
D7: BUILDING CODE (if anonymisation) | E7: W_Steel_1970_1
D8: CONTEXT | E8: Urban
D9: CITY | E9: Sheffield
D10: REGION | E10: South Yorkshire
D11: COUNTRY | E11: United Kingdom of Great Britain and Northern Ireland (the)
D12: WORLD SUB-REGION | E12: =IF(E11="","",VLOOKUP(E11,Countries,2,FALSE)) -> Northern Europe
D13: WORLD REGION | E13: =IF(E12="","",VLOOKUP(E11,Countries,3,FALSE)) -> Europe
C15: ⍰ | D15: • Archetypical information
D16: International
D17: USE (predominant) | E17: Warehouse
D18: STRUCTURAL (predominant) | E18: Steel frame (in-situ floor)
D19: NUMBER OF STOREYS (aboveground) | E19: 0-3
C21: ⍰ | D21: Bespoke (create your own archetype classification)
D22: Use (UK classification) | E22: Storage/Warehousing
D23: Construction year (decade) | E23: 1970
D24: Structure | E24: Steel
C26: ⍰ | D26: • Building project information
C27: ⍰ | D27: NATURE OF WORK | E27: New build
D28: YEAR OF CONSTRUCTION | E28: 1973
C29: ⍰ | D29: Year(s) of renovation | E29: NA
C30: ⍰ | D30: Year(s) of extension | E30: NA
C31: ⍰ | D31: Shape complexity (on-plan) | E31: Square, rectangular or similar
D32: Shape complexity (vertical section) | E32: Square, rectangular or similar
C34: ⍰ | D34: • Building dimensions
C35: ⍰ | D35: Elevation & Section | G35: Plan-view
C36: ⍰ | D36: NUMBER OF STORIES (total) | E36: 2 | G36: PERIMETER (m) | H36: 70.6
D37: Aboveground | E37: 2 | F37: ⍰ | G37: BUILDING FOOTPRINT (m2) | H37: 298.2
D38: Underground | E38: 0 | F38: ⍰ | G38: Building footprint from above (m2) | H38: 298.2
C39: ⍰ | D39: AVERAGE STORY HEIGHT (m) | E39: 2.7 | F39: ⍰ | G39: GROSS EXTERNAL FLOOR AREA (m2) | H39: 386
C40: ⍰ | D40: AVERAGE FLOOR-TO-CEILING HEIGHT (m) | E40: 2.5 | F40: ⍰ | G40: GROSS INTERNAL FLOOR AREA (m2) | H40: 361
C41: ⍰ | D41: HEIGHT - to highest point of building (m) | E41: 6.5 | F41: ⍰ | G41: NET FLOOR AREA (m2) | H41: 357
C42: ⍰ | D42: HEIGHT - eaves (m) | E42: 5.2 | F42: ⍰ | G42: Useable area (m2) | H42: 337.5
C43: ⍰ | D43: EXTERNAL WALLS AREA (m2) | E43: 347 | F43: ⍰ | G43: Service area (m2) | H43: 13.4
C44: ⍰ | D44: GLAZING AREA (m2) | E44: 31 | F44: ⍰ | G44: Circulation area (m2) | H44: 6.1
D45: Volume | F45: ⍰ | G45: CONSTRUCTION AREA (m2) | H45: 29
C46: ⍰ | D46: GROSS VOLUME (m3) | E46: 1678 | F46: ⍰ | G46: FLOOR SPACES NOT ENCLOSED (m2) | H46: 0
C47: ⍰ | D47: GROSS VOLUME ABOVEGROUND (m3) | E47: 1678
...

Sheet Scope & Data
C3: ⍰ | D3: SCOPE of STUDY
D4: • Materials under investigation
C5: ⍰ | D5: All building material | E5: 1
D6: NOTE: "All building materials" (above) is set as default and thus marked with a "1".
D7: If the study focuses on specific materials, delete the "1" above, and tag those specific materials with "1" in the table below.
D8: Bio-based | H8: Other construction minerals | L8: Other materials
D9: Wood | H9: Adobe | L9: Carpet
D10: Paper/Cardboard | H10: Asphalt | L10: Ceramics
D11: Straw | H11: Bitumen | L11: Glass
D12: Metals | H12: Brick | L12: Linoleum
D13: Steel | H13: Cement asbestos sheet | L13: Mineral Wool
D14: Copper | H14: Clay | L14: Plastics
D15: Aluminum | H15: Mineral fill | L15: Polystyrene
D16: Other metals | H16: Mortar/Plaster | L16: PVC
D17: Concrete, cement and aggregate | H17: Natural Stone | L17: Woodwool insulation (heraklith)
D18: Concrete | H18: Plasterboards/gypsum | L18: Other insulation
D19: Cement | H19: Siding (unspecified material) | L19: Other (specify in the cell below)
D20: Aggregate (gravel, sand, slag)
D22: • Parts of the building
D23: Tag the building shearing layers included in the study with "1" in the table below. | H23: Tag the vertical parts of the structure included in the study with "1" in the table below.
C24: ⍰ | D24: SHEARING LAYERS | G24: ⍰ | H24: VERTICAL SCOPE
D25: Structure | E25: 1 | H25: Superstructure | I25: 1
D26: Skin | E26: 1 | H26: Substructure | I26: 1
D27: Space | E27: 1 | H27: Foundations' compact layers included
C29: ⍰ | D29: DATA COLLECTION
D30: Mark relevant information with a 1 in the cell to its right
C31: ⍰ | D31: DATA SOURCES | G31: ⍰ | H31: CATEGORY OF BUILDING DATA
D32: BIM data | H32: Architectural data | I32: 1
D33: Construction documents (e.g., plans, specs) | E33: 1 | H33: Structural data
D34: Digital off-site survey | E34: 1 | G34: ⍰ | H34: MEP data
D35: Digital on-site survey
D36: Manual on-site survey - destructive
D37: Manual on-site survey - non-destructive
D38: Demolition permit
D39: Waste management plan prior to demolition
D40: Materials delivery records
D41: Readily available BoM
D42: Other (specify in the cell below)
C45: ⍰ | D45: STATUS of ANALYSIS & PROCESS TRACKING
D46: Main analysis conducted by | E46: PYL
...

Sheet Bill of material
A2: ⍰ | B2: DATA COLLECTION
B3: Item description ⍰ | H3: Calculation of item dimension ⍰ | V3: Item's material ⍰ | AC3: Item's weight and volume ⍰
B4: Item ⍰ | C4: Description ⍰ | D4: Comments/assumptions ⍰ | E4: Super/Sub | F4: Building element | G4: Shearing layer | H4: Calculation method ⍰ | J4: Quantity | K4: Length | L4: Height | M4: Thickness | N4: Area | O4: Cross-section | P4: Volume | Q4: Mass | R4: Rule of thumb ⍰ | T4: Item's dimension ⍰ | V4: Material category ⍰ | AA4: Density ⍰ | AC4: Weight | AD4: Volumic density | AE4: Volume | AF4: Material type ⍰
B5: e.g., "Foundation footing", "External door", "Floor slab", "Roof cover", … | C5: e.g., "Foundation: concrete", "Foundation: reinforcement", "Window: frame", "Window: glass", … | D5: e.g., "thickness assumed as 215mm"; "unspecified material: assumed timber" | E5: ⍰ | F5: ⍰ | G5: ⍰ | H5: Target dimension | I5: Calculation method | J5: Q [#] | K5: L [m] | L5: H [m] | M5: T [m] | N5: A [m2] | O5: CS [m2] | P5: V [m3] | Q5: M [kg] | R5: RoT value ⍰ | S5: Reference quantity ⍰ | T5: Result | U5: Unit | V5: Level 1 | W5: Level 2 | X5: Level 3 | Y5: Level 4 | Z5: Other material? ⍰ (specify) | AA5: Value | AB5: Unit | AC5: (kg) | AD5: (kg/m3) | AE5: (m3) | AF5: Used for result summary
B6: Reinforced concrete pad foundations 1.8X1.8 - concrete | E6: Sub | F6: Foundations | G6: Structure | H6: Volume | I6: V = L x H x T | J6: 6 | K6: 1.8 | L6: 1.8 | M6: 0.3 | T6: {=_xlfn.IFS(I6="L = L",J6*K6,I6="L = RoT",J6*R6*S6,I6="A = L x H",J6*K6*L6,I6="A = CS",J6*O6,I6="A = A",J6*N6,I6="A = RoT",J6*R6*S6,I6="V = L x H x T",J6*K6*L6*M6,I6="V = L x CS",J6*K6*O6,I6="V = T x A",J6*M6*N6,I6="V = V",J6*P6,I6="V = RoT",J6*R6*S6,I6="M = M",J6*Q6,I6="M = RoT",J6*R6*S6,I6="","")} -> 5.832 | U6: {=_xlfn.IFNA(_xlfn.IFS($H6="length","m",$H6="area","m2",$H6="volume","m3",$H6="mass","kg",$H6="",""),"problem")} -> m3 | V6: In situ cementitious | W6: Concrete in situ | X6: Concrete in situ general | Y6: Concrete in situ general | AA6: {=_xlfn.IFNA(_xlfn.IFS($H6="Length",VLOOKUP($Y6,Densities,3,FALSE),$H6="area",VLOOKUP($Y6,Densities,4,FALSE),$H6="volume",VLOOKUP($Y6,Densities,5,FALSE),$H6="mass",1,$H6="",""),"enter density manually")} -> 2400 | AB6: {=_xlfn.IFNA(_xlfn.IFS($H6="length","kg/m",$H6="area","kg/m2",$H6="volume","kg/m3",$H6="mass","kg/kg",$H6="",""),"problem")} -> kg/m3 | AC6: =IF($T6="","",$T6*$AA6) -> 13996.8 | AD6: =IF($Y6="","",IFERROR(_xlfn.IFNA(IF($H6="volume",$AA6,VLOOKUP($Y6,Densities,5,FALSE)),"enter volumic density manually"),"enter volumic density manually")) -> 2400 | AE6: =IF($Y6="","",IF($AC6="","",$AC6/$AD6)) -> 5.832 | AF6: =_xlfn.IFNA(IF($Y6="","",VLOOKUP($Y6,_xlfn.CHOOSECOLS(Material_categories,4,9),2,FALSE)),"Assign material to its type in tab 'Matching of material categories'") -> Concrete and cementitious
B7: Reinforced concrete pad foundations 1.8X1.8 - reinforcement | D7: Rule of thumb | E7: Sub | F7: Foundations | G7: Structure | H7: Mass | I7: M = RoT | J7: 1 | R7: 80 | S7: 5.832 | T7: {=_xlfn.IFS(I7="L = L",J7*K7,I7="L = RoT",J7*R7*S7,I7="A = L x H",J7*K7*L7,I7="A = CS",J7*O7,I7="A = A",J7*N7,I7="A = RoT",J7*R7*S7,I7="V = L x H x T",J7*K7*L7*M7,I7="V = L x CS",J7*K7*O7,I7="V = T x A",J7*M7*N7,I7="V = V",J7*P7,I7="V = RoT",J7*R7*S7,I7="M = M",J7*Q7,I7="M = RoT",J7*R7*S7,I7="","")} -> 466.56 | U7: {=_xlfn.IFNA(_xlfn.IFS($H7="length","m",$H7="area","m2",$H7="volume","m3",$H7="mass","kg",$H7="",""),"problem")} -> kg | V7: Steel and metals | W7: Steel framing and reinforcement | X7: Reinforcement in concrete | Y7: Rebar | AA7: {=_xlfn.IFNA(_xlfn.IFS($H7="Length",VLOOKUP($Y7,Densities,3,FALSE),$H7="area",VLOOKUP($Y7,Densities,4,FALSE),$H7="volume",VLOOKUP($Y7,Densities,5,FALSE),$H7="mass",1,$H7="",""),"enter density manually")} -> 1 | AB7: {=_xlfn.IFNA(_xlfn.IFS($H7="length","kg/m",$H7="area","kg/m2",$H7="volume","kg/m3",$H7="mass","kg/kg",$H7="",""),"problem")} -> kg/kg | AC7: =IF($T7="","",$T7*$AA7) -> 466.56 | AD7: =IF($Y7="","",IFERROR(_xlfn.IFNA(IF($H7="volume",$AA7,VLOOKUP($Y7,Densities,5,FALSE)),"enter volumic density manually"),"enter volumic density manually")) -> 7800 | AE7: =IF($Y7="","",IF($AC7="","",$AC7/$AD7)) -> 0.059815385 | AF7: =_xlfn.IFNA(IF($Y7="","",VLOOKUP($Y7,_xlfn.CHOOSECOLS(Material_categories,4,9),2,FALSE)),"Assign material to its type in tab 'Matching of material categories'") -> Metal - steel
B8: Reinforced concrete pad foundations 2.4X2.4 - concrete | E8: Sub | F8: Foundations | G8: Structure | H8: Volume | I8: V = L x H x T | J8: 8 | K8: 2.4 | L8: 2.4 | M8: 0.3 | T8: {=_xlfn.IFS(I8="L = L",J8*K8,I8="L = RoT",J8*R8*S8,I8="A = L x H",J8*K8*L8,I8="A = CS",J8*O8,I8="A = A",J8*N8,I8="A = RoT",J8*R8*S8,I8="V = L x H x T",J8*K8*L8*M8,I8="V = L x CS",J8*K8*O8,I8="V = T x A",J8*M8*N8,I8="V = V",J8*P8,I8="V = RoT",J8*R8*S8,I8="M = M",J8*Q8,I8="M = RoT",J8*R8*S8,I8="","")} -> 13.824 | U8: {=_xlfn.IFNA(_xlfn.IFS($H8="length","m",$H8="area","m2",$H8="volume","m3",$H8="mass","kg",$H8="",""),"problem")} -> m3 | V8: In situ cementitious | W8: Concrete in situ | X8: Concrete in situ general | Y8: Concrete in situ general | AA8: {=_xlfn.IFNA(_xlfn.IFS($H8="Length",VLOOKUP($Y8,Densities,3,FALSE),$H8="area",VLOOKUP($Y8,Densities,4,FALSE),$H8="volume",VLOOKUP($Y8,Densities,5,FALSE),$H8="mass",1,$H8="",""),"enter density manually")} -> 2400 | AB8: {=_xlfn.IFNA(_xlfn.IFS($H8="length","kg/m",$H8="area","kg/m2",$H8="volume","kg/m3",$H8="mass","kg/kg",$H8="",""),"problem")} -> kg/m3 | AC8: =IF($T8="","",$T8*$AA8) -> 33177.6 | AD8: =IF($Y8="","",IFERROR(_xlfn.IFNA(IF($H8="volume",$AA8,VLOOKUP($Y8,Densities,5,FALSE)),"enter volumic density manually"),"enter volumic density manually")) -> 2400 | AE8: =IF($Y8="","",IF($AC8="","",$AC8/$AD8)) -> 13.824 | AF8: =_xlfn.IFNA(IF($Y8="","",VLOOKUP($Y8,_xlfn.CHOOSECOLS(Material_categories,4,9),2,FALSE)),"Assign material to its type in tab 'Matching of material categories'") -> Concrete and cementitious
B9: Reinforced concrete pad foundations 2.4X2.4 - reinforcement | C9: Reinforcement | D9: Rule of thumb | E9: Sub | F9: Foundations | G9: Structure | H9: Mass | I9: M = RoT | J9: 1 | R9: 80 | S9: 13.824 | T9: {=_xlfn.IFS(I9="L = L",J9*K9,I9="L = RoT",J9*R9*S9,I9="A = L x H",J9*K9*L9,I9="A = CS",J9*O9,I9="A = A",J9*N9,I9="A = RoT",J9*R9*S9,I9="V = L x H x T",J9*K9*L9*M9,I9="V = L x CS",J9*K9*O9,I9="V = T x A",J9*M9*N9,I9="V = V",J9*P9,I9="V = RoT",J9*R9*S9,I9="M = M",J9*Q9,I9="M = RoT",J9*R9*S9,I9="","")} -> 1105.92 | U9: {=_xlfn.IFNA(_xlfn.IFS($H9="length","m",$H9="area","m2",$H9="volume","m3",$H9="mass","kg",$H9="",""),"problem")} -> kg | V9: In situ cementitious | W9: Concrete in situ | X9: Concrete in situ general | Y9: Concrete in situ general | AA9: {=_xlfn.IFNA(_xlfn.IFS($H9="Length",VLOOKUP($Y9,Densities,3,FALSE),$H9="area",VLOOKUP($Y9,Densities,4,FALSE),$H9="volume",VLOOKUP($Y9,Densities,5,FALSE),$H9="mass",1,$H9="",""),"enter density manually")} -> 1 | AB9: {=_xlfn.IFNA(_xlfn.IFS($H9="length","kg/m",$H9="area","kg/m2",$H9="volume","kg/m3",$H9="mass","kg/kg",$H9="",""),"problem")} -> kg/kg | AC9: =IF($T9="","",$T9*$AA9) -> 1105.92 | AD9: =IF($Y9="","",IFERROR(_xlfn.IFNA(IF($H9="volume",$AA9,VLOOKUP($Y9,Densities,5,FALSE)),"enter volumic density manually"),"enter volumic density manually")) -> 2400 | AE9: =IF($Y9="","",IF($AC9="","",$AC9/$AD9)) -> 0.4608 | AF9: =_xlfn.IFNA(IF($Y9="","",VLOOKUP($Y9,_xlfn.CHOOSECOLS(Material_categories,4,9),2,FALSE)),"Assign material to its type in tab 'Matching of material categories'") -> Concrete and cementitious
B10: Reinforced concrete perimeter edge beam - concrete | E10: Sub | F10: Foundations | G10: Structure | H10: Volume | I10: V = L x CS | J10: 1 | K10: 70.6 | O10: 0.09 | T10: {=_xlfn.IFS(I10="L = L",J10*K10,I10="L = RoT",J10*R10*S10,I10="A = L x H",J10*K10*L10,I10="A = CS",J10*O10,I10="A = A",J10*N10,I10="A = RoT",J10*R10*S10,I10="V = L x H x T",J10*K10*L10*M10,I10="V = L x CS",J10*K10*O10,I10="V = T x A",J10*M10*N10,I10="V = V",J10*P10,I10="V = RoT",J10*R10*S10,I10="M = M",J10*Q10,I10="M = RoT",J10*R10*S10,I10="","")} -> 6.354 | U10: {=_xlfn.IFNA(_xlfn.IFS($H10="length","m",$H10="area","m2",$H10="volume","m3",$H10="mass","kg",$H10="",""),"problem")} -> m3 | V10: In situ cementitious | W10: Concrete in situ | X10: Concrete in situ general | Y10: Concrete in situ general | AA10: {=_xlfn.IFNA(_xlfn.IFS($H10="Length",VLOOKUP($Y10,Densities,3,FALSE),$H10="area",VLOOKUP($Y10,Densities,4,FALSE),$H10="volume",VLOOKUP($Y10,Densities,5,FALSE),$H10="mass",1,$H10="",""),"enter density manually")} -> 2400 | AB10: {=_xlfn.IFNA(_xlfn.IFS($H10="length","kg/m",$H10="area","kg/m2",$H10="volume","kg/m3",$H10="mass","kg/kg",$H10="",""),"problem")} -> kg/m3 | AC10: =IF($T10="","",$T10*$AA10) -> 15249.6 | AD10: =IF($Y10="","",IFERROR(_xlfn.IFNA(IF($H10="volume",$AA10,VLOOKUP($Y10,Densities,5,FALSE)),"enter volumic density manually"),"enter volumic density manually")) -> 2400 | AE10: =IF($Y10="","",IF($AC10="","",$AC10/$AD10)) -> 6.354 | AF10: =_xlfn.IFNA(IF($Y10="","",VLOOKUP($Y10,_xlfn.CHOOSECOLS(Material_categories,4,9),2,FALSE)),"Assign material to its type in tab 'Matching of material categories'") -> Concrete and cementitious
B11: Reinforced concrete perimeter edge beam - reinforcement | C11: Reinforcement | D11: Rule of thumb | E11: Sub | F11: Foundations | G11: Structure | H11: Mass | I11: M = RoT | J11: 1 | R11: 255 | S11: 6.354 | T11: {=_xlfn.IFS(I11="L = L",J11*K11,I11="L = RoT",J11*R11*S11,I11="A = L x H",J11*K11*L11,I11="A = CS",J11*O11,I11="A = A",J11*N11,I11="A = RoT",J11*R11*S11,I11="V = L x H x T",J11*K11*L11*M11,I11="V = L x CS",J11*K11*O11,I11="V = T x A",J11*M11*N11,I11="V = V",J11*P11,I11="V = RoT",J11*R11*S11,I11="M = M",J11*Q11,I11="M = RoT",J11*R11*S11,I11="","")} -> 1620.27 | U11: {=_xlfn.IFNA(_xlfn.IFS($H11="length","m",$H11="area","m2",$H11="volume","m3",$H11="mass","kg",$H11="",""),"problem")} -> kg | V11: In situ cementitious | W11: Concrete in situ | X11: Concrete in situ general | Y11: Concrete in situ general | AA11: {=_xlfn.IFNA(_xlfn.IFS($H11="Length",VLOOKUP($Y11,Densities,3,FALSE),$H11="area",VLOOKUP($Y11,Densities,4,FALSE),$H11="volume",VLOOKUP($Y11,Densities,5,FALSE),$H11="mass",1,$H11="",""),"enter density manually")} -> 1 | AB11: {=_xlfn.IFNA(_xlfn.IFS($H11="length","kg/m",$H11="area","kg/m2",$H11="volume","kg/m3",$H11="mass","kg/kg",$H11="",""),"problem")} -> kg/kg | AC11: =IF($T11="","",$T11*$AA11) -> 1620.27 | AD11: =IF($Y11="","",IFERROR(_xlfn.IFNA(IF($H11="volume",$AA11,VLOOKUP($Y11,Densities,5,FALSE)),"enter volumic density manually"),"enter volumic density manually")) -> 2400 | AE11: =IF($Y11="","",IF($AC11="","",$AC11/$AD11)) -> 0.6751125 | AF11: =_xlfn.IFNA(IF($Y11="","",VLOOKUP($Y11,_xlfn.CHOOSECOLS(Material_categories,4,9),2,FALSE)),"Assign material to its type in tab 'Matching of material categories'") -> Concrete and cementitious
B12: Reinforced concrete ground floor slab - concrete | E12: Sub | F12: Lowest floor | G12: Structure | H12: Volume | I12: V = T x A | J12: 1 | M12: 0.15 | N12: 298.2 | T12: {=_xlfn.IFS(I12="L = L",J12*K12,I12="L = RoT",J12*R12*S12,I12="A = L x H",J12*K12*L12,I12="A = CS",J12*O12,I12="A = A",J12*N12,I12="A = RoT",J12*R12*S12,I12="V = L x H x T",J12*K12*L12*M12,I12="V = L x CS",J12*K12*O12,I12="V = T x A",J12*M12*N12,I12="V = V",J12*P12,I12="V = RoT",J12*R12*S12,I12="M = M",J12*Q12,I12="M = RoT",J12*R12*S12,I12="","")} -> 44.73 | U12: {=_xlfn.IFNA(_xlfn.IFS($H12="length","m",$H12="area","m2",$H12="volume","m3",$H12="mass","kg",$H12="",""),"problem")} -> m3 | V12: In situ cementitious | W12: Concrete in situ | X12: Concrete in situ general | Y12: Concrete in situ general | AA12: {=_xlfn.IFNA(_xlfn.IFS($H12="Length",VLOOKUP($Y12,Densities,3,FALSE),$H12="area",VLOOKUP($Y12,Densities,4,FALSE),$H12="volume",VLOOKUP($Y12,Densities,5,FALSE),$H12="mass",1,$H12="",""),"enter density manually")} -> 2400 | AB12: {=_xlfn.IFNA(_xlfn.IFS($H12="length","kg/m",$H12="area","kg/m2",$H12="volume","kg/m3",$H12="mass","kg/kg",$H12="",""),"problem")} -> kg/m3 | AC12: =IF($T12="","",$T12*$AA12) -> 107352 | AD12: =IF($Y12="","",IFERROR(_xlfn.IFNA(IF($H12="volume",$AA12,VLOOKUP($Y12,Densities,5,FALSE)),"enter volumic density manually"),"enter volumic density manually")) -> 2400 | AE12: =IF($Y12="","",IF($AC12="","",$AC12/$AD12)) -> 44.73 | AF12: =_xlfn.IFNA(IF($Y12="","",VLOOKUP($Y12,_xlfn.CHOOSECOLS(Material_categories,4,9),2,FALSE)),"Assign material to its type in tab 'Matching of material categories'") -> Concrete and cementitious
B13: Reinforced concrete ground floor slab - reinforcement | C13: Reinforcement | D13: Rule of thumb | E13: Sub | F13: Lowest floor | G13: Structure | H13: Mass | I13: M = RoT | J13: 1 | R13: 100 | S13: 44.73 | T13: {=_xlfn.IFS(I13="L = L",J13*K13,I13="L = RoT",J13*R13*S13,I13="A = L x H",J13*K13*L13,I13="A = CS",J13*O13,I13="A = A",J13*N13,I13="A = RoT",J13*R13*S13,I13="V = L x H x T",J13*K13*L13*M13,I13="V = L x CS",J13*K13*O13,I13="V = T x A",J13*M13*N13,I13="V = V",J13*P13,I13="V = RoT",J13*R13*S13,I13="M = M",J13*Q13,I13="M = RoT",J13*R13*S13,I13="","")} -> 4473 | U13: {=_xlfn.IFNA(_xlfn.IFS($H13="length","m",$H13="area","m2",$H13="volume","m3",$H13="mass","kg",$H13="",""),"problem")} -> kg | V13: In situ cementitious | W13: Concrete in situ | X13: Concrete in situ general | Y13: Concrete in situ general | AA13: {=_xlfn.IFNA(_xlfn.IFS($H13="Length",VLOOKUP($Y13,Densities,3,FALSE),$H13="area",VLOOKUP($Y13,Densities,4,FALSE),$H13="volume",VLOOKUP($Y13,Densities,5,FALSE),$H13="mass",1,$H13="",""),"enter density manually")} -> 1 | AB13: {=_xlfn.IFNA(_xlfn.IFS($H13="length","kg/m",$H13="area","kg/m2",$H13="volume","kg/m3",$H13="mass","kg/kg",$H13="",""),"problem")} -> kg/kg | AC13: =IF($T13="","",$T13*$AA13) -> 4473 | AD13: =IF($Y13="","",IFERROR(_xlfn.IFNA(IF($H13="volume",$AA13,VLOOKUP($Y13,Densities,5,FALSE)),"enter volumic density manually"),"enter volumic density manually")) -> 2400 | AE13: =IF($Y13="","",IF($AC13="","",$AC13/$AD13)) -> 1.86375 | AF13: =_xlfn.IFNA(IF($Y13="","",VLOOKUP($Y13,_xlfn.CHOOSECOLS(Material_categories,4,9),2,FALSE)),"Assign material to its type in tab 'Matching of material categories'") -> Concrete and cementitious
B14: Visqueen 1200 DP membrane under ground floor | C14: 1200 gauge DPM Membrane for Concrete Floors | D14: Thickness assumed 300μm | E14: Sub | F14: Lowest floor | G14: Structure | H14: Volume | I14: V = T x A | J14: 1 | M14: 0.0003 | N14: 298.2 | T14: {=_xlfn.IFS(I14="L = L",J14*K14,I14="L = RoT",J14*R14*S14,I14="A = L x H",J14*K14*L14,I14="A = CS",J14*O14,I14="A = A",J14*N14,I14="A = RoT",J14*R14*S14,I14="V = L x H x T",J14*K14*L14*M14,I14="V = L x CS",J14*K14*O14,I14="V = T x A",J14*M14*N14,I14="V = V",J14*P14,I14="V = RoT",J14*R14*S14,I14="M = M",J14*Q14,I14="M = RoT",J14*R14*S14,I14="","")} -> 0.08946 | U14: {=_xlfn.IFNA(_xlfn.IFS($H14="length","m",$H14="area","m2",$H14="volume","m3",$H14="mass","kg",$H14="",""),"problem")} -> m3 | V14: Weatherproofing and plastics | W14: Weatherproofing membranes | X14: Damp proofing | Y14: Damp proof membrane LDPE 0.3mm | AA14: {=_xlfn.IFNA(_xlfn.IFS($H14="Length",VLOOKUP($Y14,Densities,3,FALSE),$H14="area",VLOOKUP($Y14,Densities,4,FALSE),$H14="volume",VLOOKUP($Y14,Densities,5,FALSE),$H14="mass",1,$H14="",""),"enter density manually")} -> 939 | AB14: {=_xlfn.IFNA(_xlfn.IFS($H14="length","kg/m",$H14="area","kg/m2",$H14="volume","kg/m3",$H14="mass","kg/kg",$H14="",""),"problem")} -> kg/m3 | AC14: =IF($T14="","",$T14*$AA14) -> 84.00294 | AD14: =IF($Y14="","",IFERROR(_xlfn.IFNA(IF($H14="volume",$AA14,VLOOKUP($Y14,Densities,5,FALSE)),"enter volumic density manually"),"enter volumic density manually")) -> 939 | AE14: =IF($Y14="","",IF($AC14="","",$AC14/$AD14)) -> 0.08946 | AF14: =_xlfn.IFNA(IF($Y14="","",VLOOKUP($Y14,_xlfn.CHOOSECOLS(Material_categories,4,9),2,FALSE)),"Assign material to its type in tab 'Matching of material categories'") -> Plastics
B15: Hardcore base | C15: Aggregates | D15: Assumed 200mm hardcore base | E15: Sub | F15: Lowest floor | G15: Structure | H15: Volume | I15: V = T x A | J15: 1 | M15: 0.2 | N15: 298.2 | T15: {=_xlfn.IFS(I15="L = L",J15*K15,I15="L = RoT",J15*R15*S15,I15="A = L x H",J15*K15*L15,I15="A = CS",J15*O15,I15="A = A",J15*N15,I15="A = RoT",J15*R15*S15,I15="V = L x H x T",J15*K15*L15*M15,I15="V = L x CS",J15*K15*O15,I15="V = T x A",J15*M15*N15,I15="V = V",J15*P15,I15="V = RoT",J15*R15*S15,I15="M = M",J15*Q15,I15="M = RoT",J15*R15*S15,I15="","")} -> 59.64 | U15: {=_xlfn.IFNA(_xlfn.IFS($H15="length","m",$H15="area","m2",$H15="volume","m3",$H15="mass","kg",$H15="",""),"problem")} -> m3 | V15: Aggregates sand stones | W15: Aggregates | X15: Aggregates general | Y15: Aggregates and sand general | AA15: {=_xlfn.IFNA(_xlfn.IFS($H15="Length",VLOOKUP($Y15,Densities,3,FALSE),$H15="area",VLOOKUP($Y15,Densities,4,FALSE),$H15="volume",VLOOKUP($Y15,Densities,5,FALSE),$H15="mass",1,$H15="",""),"enter density manually")} -> 1669 | AB15: {=_xlfn.IFNA(_xlfn.IFS($H15="length","kg/m",$H15="area","kg/m2",$H15="volume","kg/m3",$H15="mass","kg/kg",$H15="",""),"problem")} -> kg/m3 | AC15: =IF($T15="","",$T15*$AA15) -> 99539.16 | AD15: =IF($Y15="","",IFERROR(_xlfn.IFNA(IF($H15="volume",$AA15,VLOOKUP($Y15,Densities,5,FALSE)),"enter volumic density manually"),"enter volumic density manually")) -> 1669 | AE15: =IF($Y15="","",IF($AC15="","",$AC15/$AD15)) -> 59.64 | AF15: =_xlfn.IFNA(IF($Y15="","",VLOOKUP($Y15,_xlfn.CHOOSECOLS(Material_categories,4,9),2,FALSE)),"Assign material to its type in tab 'Matching of material categories'") -> Aggregates, sand, stones
B16: External walls: brick facing outer skin | D16: Assumed 125mm; Wall area is excluding door and window area | E16: Super | F16: External walls | G16: Skin | H16: Volume | I16: V = T x A | J16: 1 | M16: 0.125 | N16: 312.52 | T16: {=_xlfn.IFS(I16="L = L",J16*K16,I16="L = RoT",J16*R16*S16,I16="A = L x H",J16*K16*L16,I16="A = CS",J16*O16,I16="A = A",J16*N16,I16="A = RoT",J16*R16*S16,I16="V = L x H x T",J16*K16*L16*M16,I16="V = L x CS",J16*K16*O16,I16="V = T x A",J16*M16*N16,I16="V = V",J16*P16,I16="V = RoT",J16*R16*S16,I16="M = M",J16*Q16,I16="M = RoT",J16*R16*S16,I16="","")} -> 39.065 | U16: {=_xlfn.IFNA(_xlfn.IFS($H16="length","m",$H16="area","m2",$H16="volume","m3",$H16="mass","kg",$H16="",""),"problem")} -> m3 | V16: Blocks bricks and precast products | W16: Solid brick | X16: Clay brick | Y16: Brick unit | AA16: {=_xlfn.IFNA(_xlfn.IFS($H16="Length",VLOOKUP($Y16,Densities,3,FALSE),$H16="area",VLOOKUP($Y16,Densities,4,FALSE),$H16="volume",VLOOKUP($Y16,Densities,5,FALSE),$H16="mass",1,$H16="",""),"enter density manually")} -> 1650 | AB16: {=_xlfn.IFNA(_xlfn.IFS($H16="length","kg/m",$H16="area","kg/m2",$H16="volume","kg/m3",$H16="mass","kg/kg",$H16="",""),"problem")} -> kg/m3 | AC16: =IF($T16="","",$T16*$AA16) -> 64457.25 | AD16: =IF($Y16="","",IFERROR(_xlfn.IFNA(IF($H16="volume",$AA16,VLOOKUP($Y16,Densities,5,FALSE)),"enter volumic density manually"),"enter volumic density manually")) -> 1650 | AE16: =IF($Y16="","",IF($AC16="","",$AC16/$AD16)) -> 39.065 | AF16: =_xlfn.IFNA(IF($Y16="","",VLOOKUP($Y16,_xlfn.CHOOSECOLS(Material_categories,4,9),2,FALSE)),"Assign material to its type in tab 'Matching of material categories'") -> Bricks and ceramics
B17: External walls: grey concrete inner skin | D17: Assumed 125mm; Wall area is excluding door and window area | E17: Super | F17: External walls | G17: Skin | H17: Volume | I17: V = T x A | J17: 1 | M17: 0.125 | N17: 312.52 | T17: {=_xlfn.IFS(I17="L = L",J17*K17,I17="L = RoT",J17*R17*S17,I17="A = L x H",J17*K17*L17,I17="A = CS",J17*O17,I17="A = A",J17*N17,I17="A = RoT",J17*R17*S17,I17="V = L x H x T",J17*K17*L17*M17,I17="V = L x CS",J17*K17*O17,I17="V = T x A",J17*M17*N17,I17="V = V",J17*P17,I17="V = RoT",J17*R17*S17,I17="M = M",J17*Q17,I17="M = RoT",J17*R17*S17,I17="","")} -> 39.065 | U17: {=_xlfn.IFNA(_xlfn.IFS($H17="length","m",$H17="area","m2",$H17="volume","m3",$H17="mass","kg",$H17="",""),"problem")} -> m3 | V17: Blocks bricks and precast products | W17: Hollow block | X17: Concrete | Y17: Normal weight | AA17: {=_xlfn.IFNA(_xlfn.IFS($H17="Length",VLOOKUP($Y17,Densities,3,FALSE),$H17="area",VLOOKUP($Y17,Densities,4,FALSE),$H17="volume",VLOOKUP($Y17,Densities,5,FALSE),$H17="mass",1,$H17="",""),"enter density manually")} -> 2000 | AB17: {=_xlfn.IFNA(_xlfn.IFS($H17="length","kg/m",$H17="area","kg/m2",$H17="volume","kg/m3",$H17="mass","kg/kg",$H17="",""),"problem")} -> kg/m3 | AC17: =IF($T17="","",$T17*$AA17) -> 78130 | AD17: =IF($Y17="","",IFERROR(_xlfn.IFNA(IF($H17="volume",$AA17,VLOOKUP($Y17,Densities,5,FALSE)),"enter volumic density manually"),"enter volumic density manually")) -> 2000 | AE17: =IF($Y17="","",IF($AC17="","",$AC17/$AD17)) -> 39.065 | AF17: =_xlfn.IFNA(IF($Y17="","",VLOOKUP($Y17,_xlfn.CHOOSECOLS(Material_categories,4,9),2,FALSE)),"Assign material to its type in tab 'Matching of material categories'") -> Concrete and cementitious
B18: Vertical expansion joints in 9.5 flexcell in 3 sides (apart north) @ 12m crs | C18: bitumen impregnated wood fibre board | E18: Super | F18: External walls | G18: Skin | H18: Volume | I18: V = L x H x T | J18: 4 | K18: 0.2875 | L18: 6.7 | M18: 0.0095 | T18: {=_xlfn.IFS(I18="L = L",J18*K18,I18="L = RoT",J18*R18*S18,I18="A = L x H",J18*K18*L18,I18="A = CS",J18*O18,I18="A = A",J18*N18,I18="A = RoT",J18*R18*S18,I18="V = L x H x T",J18*K18*L18*M18,I18="V = L x CS",J18*K18*O18,I18="V = T x A",J18*M18*N18,I18="V = V",J18*P18,I18="V = RoT",J18*R18*S18,I18="M = M",J18*Q18,I18="M = RoT",J18*R18*S18,I18="","")} -> 0.0731975 | U18: {=_xlfn.IFNA(_xlfn.IFS($H18="length","m",$H18="area","m2",$H18="volume","m3",$H18="mass","kg",$H18="",""),"problem")} -> m3 | V18: Timber and engineered timber | W18: Wood products | X18: Boards | Y18: Fiberboard | AA18: {=_xlfn.IFNA(_xlfn.IFS($H18="Length",VLOOKUP($Y18,Densities,3,FALSE),$H18="area",VLOOKUP($Y18,Densities,4,FALSE),$H18="volume",VLOOKUP($Y18,Densities,5,FALSE),$H18="mass",1,$H18="",""),"enter density manually")} -> 225 | AB18: {=_xlfn.IFNA(_xlfn.IFS($H18="length","kg/m",$H18="area","kg/m2",$H18="volume","kg/m3",$H18="mass","kg/kg",$H18="",""),"problem")} -> kg/m3 | AC18: =IF($T18="","",$T18*$AA18) -> 16.469437 | AD18: =IF($Y18="","",IFERROR(_xlfn.IFNA(IF($H18="volume",$AA18,VLOOKUP($Y18,Densities,5,FALSE)),"enter volumic density manually"),"enter volumic density manually")) -> 225 | AE18: =IF($Y18="","",IF($AC18="","",$AC18/$AD18)) -> 0.0731975 | AF18: =_xlfn.IFNA(IF($Y18="","",VLOOKUP($Y18,_xlfn.CHOOSECOLS(Material_categories,4,9),2,FALSE)),"Assign material to its type in tab 'Matching of material categories'") -> Bio-based
B19: Precast concrete coping | E19: Super | F19: External walls | G19: Skin | H19: Volume | I19: V = L x CS | J19: 1 | K19: 65.1 | O19: 0.015 | T19: {=_xlfn.IFS(I19="L = L",J19*K19,I19="L = RoT",J19*R19*S19,I19="A = L x H",J19*K19*L19,I19="A = CS",J19*O19,I19="A = A",J19*N19,I19="A = RoT",J19*R19*S19,I19="V = L x H x T",J19*K19*L19*M19,I19="V = L x CS",J19*K19*O19,I19="V = T x A",J19*M19*N19,I19="V = V",J19*P19,I19="V = RoT",J19*R19*S19,I19="M = M",J19*Q19,I19="M = RoT",J19*R19*S19,I19="","")} -> 0.9765 | U19: {=_xlfn.IFNA(_xlfn.IFS($H19="length","m",$H19="area","m2",$H19="volume","m3",$H19="mass","kg",$H19="",""),"problem")} -> m3 | V19: Blocks bricks and precast products | W19: Hollow block | X19: Concrete | Y19: Normal weight | AA19: {=_xlfn.IFNA(_xlfn.IFS($H19="Length",VLOOKUP($Y19,Densities,3,FALSE),$H19="area",VLOOKUP($Y19,Densities,4,FALSE),$H19="volume",VLOOKUP($Y19,Densities,5,FALSE),$H19="mass",1,$H19="",""),"enter density manually")} -> 2000 | AB19: {=_xlfn.IFNA(_xlfn.IFS($H19="length","kg/m",$H19="area","kg/m2",$H19="volume","kg/m3",$H19="mass","kg/kg",$H19="",""),"problem")} -> kg/m3 | AC19: =IF($T19="","",$T19*$AA19) -> 1953 | AD19: =IF($Y19="","",IFERROR(_xlfn.IFNA(IF($H19="volume",$AA19,VLOOKUP($Y19,Densities,5,FALSE)),"enter volumic density manually"),"enter volumic density manually")) -> 2000 | AE19: =IF($Y19="","",IF($AC19="","",$AC19/$AD19)) -> 0.9765 | AF19: =_xlfn.IFNA(IF($Y19="","",VLOOKUP($Y19,_xlfn.CHOOSECOLS(Material_categories,4,9),2,FALSE)),"Assign material to its type in tab 'Matching of material categories'") -> Concrete and cementitious
B20: Ground floor Showroom partition walls | E20: Super | F20: Internal walls | G20: Space | H20: Volume | I20: V = V | J20: 1 | P20: 2.59 | T20: {=_xlfn.IFS(I20="L = L",J20*K20,I20="L = RoT",J20*R20*S20,I20="A = L x H",J20*K20*L20,I20="A = CS",J20*O20,I20="A = A",J20*N20,I20="A = RoT",J20*R20*S20,I20="V = L x H x T",J20*K20*L20*M20,I20="V = L x CS",J20*K20*O20,I20="V = T x A",J20*M20*N20,I20="V = V",J20*P20,I20="V = RoT",J20*R20*S20,I20="M = M",J20*Q20,I20="M = RoT",J20*R20*S20,I20="","")} -> 2.59 | U20: {=_xlfn.IFNA(_xlfn.IFS($H20="length","m",$H20="area","m2",$H20="volume","m3",$H20="mass","kg",$H20="",""),"problem")} -> m3 | V20: Blocks bricks and precast products | W20: Solid brick | X20: Clay brick | Y20: Brick unit | AA20: {=_xlfn.IFNA(_xlfn.IFS($H20="Length",VLOOKUP($Y20,Densities,3,FALSE),$H20="area",VLOOKUP($Y20,Densities,4,FALSE),$H20="volume",VLOOKUP($Y20,Densities,5,FALSE),$H20="mass",1,$H20="",""),"enter density manually")} -> 1650 | AB20: {=_xlfn.IFNA(_xlfn.IFS($H20="length","kg/m",$H20="area","kg/m2",$H20="volume","kg/m3",$H20="mass","kg/kg",$H20="",""),"problem")} -> kg/m3 | AC20: =IF($T20="","",$T20*$AA20) -> 4273.5 | AD20: =IF($Y20="","",IFERROR(_xlfn.IFNA(IF($H20="volume",$AA20,VLOOKUP($Y20,Densities,5,FALSE)),"enter volumic density manually"),"enter volumic density manually")) -> 1650 | AE20: =IF($Y20="","",IF($AC20="","",$AC20/$AD20)) -> 2.59 | AF20: =_xlfn.IFNA(IF($Y20="","",VLOOKUP($Y20,_xlfn.CHOOSECOLS(Material_categories,4,9),2,FALSE)),"Assign material to its type in tab 'Matching of material categories'") -> Bricks and ceramics
B21: Ground floor office partition walls | E21: Super | F21: Internal walls | G21: Space | H21: Volume | I21: V = V | J21: 1 | P21: 0.99 | T21: {=_xlfn.IFS(I21="L = L",J21*K21,I21="L = RoT",J21*R21*S21,I21="A = L x H",J21*K21*L21,I21="A = CS",J21*O21,I21="A = A",J21*N21,I21="A = RoT",J21*R21*S21,I21="V = L x H x T",J21*K21*L21*M21,I21="V = L x CS",J21*K21*O21,I21="V = T x A",J21*M21*N21,I21="V = V",J21*P21,I21="V = RoT",J21*R21*S21,I21="M = M",J21*Q21,I21="M = RoT",J21*R21*S21,I21="","")} -> 0.99 | U21: {=_xlfn.IFNA(_xlfn.IFS($H21="length","m",$H21="area","m2",$H21="volume","m3",$H21="mass","kg",$H21="",""),"problem")} -> m3 | V21: Blocks bricks and precast products | W21: Solid brick | X21: Clay brick | Y21: Brick unit | AA21: {=_xlfn.IFNA(_xlfn.IFS($H21="Length",VLOOKUP($Y21,Densities,3,FALSE),$H21="area",VLOOKUP($Y21,Densities,4,FALSE),$H21="volume",VLOOKUP($Y21,Densities,5,FALSE),$H21="mass",1,$H21="",""),"enter density manually")} -> 1650 | AB21: {=_xlfn.IFNA(_xlfn.IFS($H21="length","kg/m",$H21="area","kg/m2",$H21="volume","kg/m3",$H21="mass","kg/kg",$H21="",""),"problem")} -> kg/m3 | AC21: =IF($T21="","",$T21*$AA21) -> 1633.5 | AD21: =IF($Y21="","",IFERROR(_xlfn.IFNA(IF($H21="volume",$AA21,VLOOKUP($Y21,Densities,5,FALSE)),"enter volumic density manually"),"enter volumic density manually")) -> 1650 | AE21: =IF($Y21="","",IF($AC21="","",$AC21/$AD21)) -> 0.99 | AF21: =_xlfn.IFNA(IF($Y21="","",VLOOKUP($Y21,_xlfn.CHOOSECOLS(Material_categories,4,9),2,FALSE)),"Assign material to its type in tab 'Matching of material categories'") -> Bricks and ceramics
B22: Ground floor spirit store partiton walls | E22: Super | F22: Internal walls | G22: Space | H22: Volume | I22: V = V | J22: 1 | P22: 6.97 | T22: {=_xlfn.IFS(I22="L = L",J22*K22,I22="L = RoT",J22*R22*S22,I22="A = L x H",J22*K22*L22,I22="A = CS",J22*O22,I22="A = A",J22*N22,I22="A = RoT",J22*R22*S22,I22="V = L x H x T",J22*K22*L22*M22,I22="V = L x CS",J22*K22*O22,I22="V = T x A",J22*M22*N22,I22="V = V",J22*P22,I22="V = RoT",J22*R22*S22,I22="M = M",J22*Q22,I22="M = RoT",J22*R22*S22,I22="","")} -> 6.97 | U22: {=_xlfn.IFNA(_xlfn.IFS($H22="length","m",$H22="area","m2",$H22="volume","m3",$H22="mass","kg",$H22="",""),"problem")} -> m3 | V22: Blocks bricks and precast products | W22: Solid brick | X22: Clay brick | Y22: Brick unit | AA22: {=_xlfn.IFNA(_xlfn.IFS($H22="Length",VLOOKUP($Y22,Densities,3,FALSE),$H22="area",VLOOKUP($Y22,Densities,4,FALSE),$H22="volume",VLOOKUP($Y22,Densities,5,FALSE),$H22="mass",1,$H22="",""),"enter density manually")} -> 1650 | AB22: {=_xlfn.IFNA(_xlfn.IFS($H22="length","kg/m",$H22="area","kg/m2",$H22="volume","kg/m3",$H22="mass","kg/kg",$H22="",""),"problem")} -> kg/m3 | AC22: =IF($T22="","",$T22*$AA22) -> 11500.5 | AD22: =IF($Y22="","",IFERROR(_xlfn.IFNA(IF($H22="volume",$AA22,VLOOKUP($Y22,Densities,5,FALSE)),"enter volumic density manually"),"enter volumic density manually")) -> 1650 | AE22: =IF($Y22="","",IF($AC22="","",$AC22/$AD22)) -> 6.97 | AF22: =_xlfn.IFNA(IF($Y22="","",VLOOKUP($Y22,_xlfn.CHOOSECOLS(Material_categories,4,9),2,FALSE)),"Assign material to its type in tab 'Matching of material categories'") -> Bricks and ceramics
B23: First floor partition walls for male & female toilets | E23: Super | F23: Internal walls | G23: Space | H23: Volume | I23: V = L x CS | J23: 1 | K23: 9.2 | O23: 0.0475 | T23: {=_xlfn.IFS(I23="L = L",J23*K23,I23="L = RoT",J23*R23*S23,I23="A = L x H",J23*K23*L23,I23="A = CS",J23*O23,I23="A = A",J23*N23,I23="A = RoT",J23*R23*S23,I23="V = L x H x T",J23*K23*L23*M23,I23="V = L x CS",J23*K23*O23,I23="V = T x A",J23*M23*N23,I23="V = V",J23*P23,I23="V = RoT",J23*R23*S23,I23="M = M",J23*Q23,I23="M = RoT",J23*R23*S23,I23="","")} -> 0.437 | U23: {=_xlfn.IFNA(_xlfn.IFS($H23="length","m",$H23="area","m2",$H23="volume","m3",$H23="mass","kg",$H23="",""),"problem")} -> m3 | V23: Coverings claddings finishings | W23: Internal walls | X23: Plasterboard | Y23: Gypsum hardboard | AA23: {=_xlfn.IFNA(_xlfn.IFS($H23="Length",VLOOKUP($Y23,Densities,3,FALSE),$H23="area",VLOOKUP($Y23,Densities,4,FALSE),$H23="volume",VLOOKUP($Y23,Densities,5,FALSE),$H23="mass",1,$H23="",""),"enter density manually")} -> 930 | AB23: {=_xlfn.IFNA(_xlfn.IFS($H23="length","kg/m",$H23="area","kg/m2",$H23="volume","kg/m3",$H23="mass","kg/kg",$H23="",""),"problem")} -> kg/m3 | AC23: =IF($T23="","",$T23*$AA23) -> 406.41 | AD23: =IF($Y23="","",IFERROR(_xlfn.IFNA(IF($H23="volume",$AA23,VLOOKUP($Y23,Densities,5,FALSE)),"enter volumic density manually"),"enter volumic density manually")) -> 930 | AE23: =IF($Y23="","",IF($AC23="","",$AC23/$AD23)) -> 0.437 | AF23: =_xlfn.IFNA(IF($Y23="","",VLOOKUP($Y23,_xlfn.CHOOSECOLS(Material_categories,4,9),2,FALSE)),"Assign material to its type in tab 'Matching of material categories'") -> Gypsum-based
B24: Studs for first floor partition walls | D24: Assumed 75X38mm studs | E24: Super | F24: Internal walls | G24: Space | H24: Volume | I24: V = L x CS | J24: 12 | K24: 2.5 | O24: 0.00285 | T24: {=_xlfn.IFS(I24="L = L",J24*K24,I24="L = RoT",J24*R24*S24,I24="A = L x H",J24*K24*L24,I24="A = CS",J24*O24,I24="A = A",J24*N24,I24="A = RoT",J24*R24*S24,I24="V = L x H x T",J24*K24*L24*M24,I24="V = L x CS",J24*K24*O24,I24="V = T x A",J24*M24*N24,I24="V = V",J24*P24,I24="V = RoT",J24*R24*S24,I24="M = M",J24*Q24,I24="M = RoT",J24*R24*S24,I24="","")} -> 0.0855 | U24: {=_xlfn.IFNA(_xlfn.IFS($H24="length","m",$H24="area","m2",$H24="volume","m3",$H24="mass","kg",$H24="",""),"problem")} -> m3 | V24: Timber and engineered timber | W24: Timber general | X24: Timber average value | Y24: Timber average | AA24: {=_xlfn.IFNA(_xlfn.IFS($H24="Length",VLOOKUP($Y24,Densities,3,FALSE),$H24="area",VLOOKUP($Y24,Densities,4,FALSE),$H24="volume",VLOOKUP($Y24,Densities,5,FALSE),$H24="mass",1,$H24="",""),"enter density manually")} -> 526 | AB24: {=_xlfn.IFNA(_xlfn.IFS($H24="length","kg/m",$H24="area","kg/m2",$H24="volume","kg/m3",$H24="mass","kg/kg",$H24="",""),"problem")} -> kg/m3 | AC24: =IF($T24="","",$T24*$AA24) -> 44.973 | AD24: =IF($Y24="","",IFERROR(_xlfn.IFNA(IF($H24="volume",$AA24,VLOOKUP($Y24,Densities,5,FALSE)),"enter volumic density manually"),"enter volumic density manually")) -> 526 | AE24: =IF($Y24="","",IF($AC24="","",$AC24/$AD24)) -> 0.0855 | AF24: =_xlfn.IFNA(IF($Y24="","",VLOOKUP($Y24,_xlfn.CHOOSECOLS(Material_categories,4,9),2,FALSE)),"Assign material to its type in tab 'Matching of material categories'") -> Bio-based
B25: Fiberglass insulation layer in first floor partition walls | E25: Super | F25: Internal walls | G25: Space | H25: Volume | I25: V = L x CS | J25: 1 | K25: 9.2 | O25: 0.1875 | T25: {=_xlfn.IFS(I25="L = L",J25*K25,I25="L = RoT",J25*R25*S25,I25="A = L x H",J25*K25*L25,I25="A = CS",J25*O25,I25="A = A",J25*N25,I25="A = RoT",J25*R25*S25,I25="V = L x H x T",J25*K25*L25*M25,I25="V = L x CS",J25*K25*O25,I25="V = T x A",J25*M25*N25,I25="V = V",J25*P25,I25="V = RoT",J25*R25*S25,I25="M = M",J25*Q25,I25="M = RoT",J25*R25*S25,I25="","")} -> 1.725 | U25: {=_xlfn.IFNA(_xlfn.IFS($H25="length","m",$H25="area","m2",$H25="volume","m3",$H25="mass","kg",$H25="",""),"problem")} -> m3 | V25: Insulation | W25: Board | X25: Mineral board insulation | Y25: Glasswool facade board | AA25: {=_xlfn.IFNA(_xlfn.IFS($H25="Length",VLOOKUP($Y25,Densities,3,FALSE),$H25="area",VLOOKUP($Y25,Densities,4,FALSE),$H25="volume",VLOOKUP($Y25,Densities,5,FALSE),$H25="mass",1,$H25="",""),"enter density manually")} -> 55 | AB25: {=_xlfn.IFNA(_xlfn.IFS($H25="length","kg/m",$H25="area","kg/m2",$H25="volume","kg/m3",$H25="mass","kg/kg",$H25="",""),"problem")} -> kg/m3 | AC25: =IF($T25="","",$T25*$AA25) -> 94.875 | AD25: =IF($Y25="","",IFERROR(_xlfn.IFNA(IF($H25="volume",$AA25,VLOOKUP($Y25,Densities,5,FALSE)),"enter volumic density manually"),"enter volumic density manually")) -> 55 | AE25: =IF($Y25="","",IF($AC25="","",$AC25/$AD25)) -> 1.725 | AF25: =_xlfn.IFNA(IF($Y25="","",VLOOKUP($Y25,_xlfn.CHOOSECOLS(Material_categories,4,9),2,FALSE)),"Assign material to its type in tab 'Matching of material categories'") -> Insulation wools
B26: Steel portal column | E26: Super | F26: Columns | G26: Structure | H26: Volume | I26: V = L x CS | J26: 6 | K26: 5.38 | O26: 0.05 | T26: {=_xlfn.IFS(I26="L = L",J26*K26,I26="L = RoT",J26*R26*S26,I26="A = L x H",J26*K26*L26,I26="A = CS",J26*O26,I26="A = A",J26*N26,I26="A = RoT",J26*R26*S26,I26="V = L x H x T",J26*K26*L26*M26,I26="V = L x CS",J26*K26*O26,I26="V = T x A",J26*M26*N26,I26="V = V",J26*P26,I26="V = RoT",J26*R26*S26,I26="M = M",J26*Q26,I26="M = RoT",J26*R26*S26,I26="","")} -> 1.614 | U26: {=_xlfn.IFNA(_xlfn.IFS($H26="length","m",$H26="area","m2",$H26="volume","m3",$H26="mass","kg",$H26="",""),"problem")} -> m3 | V26: Steel and metals | W26: Steel framing and reinforcement | X26: Steel sections | Y26: Section | AA26: {=_xlfn.IFNA(_xlfn.IFS($H26="Length",VLOOKUP($Y26,Densities,3,FALSE),$H26="area",VLOOKUP($Y26,Densities,4,FALSE),$H26="volume",VLOOKUP($Y26,Densities,5,FALSE),$H26="mass",1,$H26="",""),"enter density manually")} -> 7800 | AB26: {=_xlfn.IFNA(_xlfn.IFS($H26="length","kg/m",$H26="area","kg/m2",$H26="volume","kg/m3",$H26="mass","kg/kg",$H26="",""),"problem")} -> kg/m3 | AC26: =IF($T26="","",$T26*$AA26) -> 12589.2 | AD26: =IF($Y26="","",IFERROR(_xlfn.IFNA(IF($H26="volume",$AA26,VLOOKUP($Y26,Densities,5,FALSE)),"enter volumic density manually"),"enter volumic density manually")) -> 7800 | AE26: =IF($Y26="","",IF($AC26="","",$AC26/$AD26)) -> 1.614 | AF26: =_xlfn.IFNA(IF($Y26="","",VLOOKUP($Y26,_xlfn.CHOOSECOLS(Material_categories,4,9),2,FALSE)),"Assign material to its type in tab 'Matching of material categories'") -> Metal - steel
B27: 150mm brick wall cladding on columns | E27: Super | F27: Internal walls | G27: Space | H27: Volume | I27: V = V | J27: 14 | P27: 0.585 | T27: {=_xlfn.IFS(I27="L = L",J27*K27,I27="L = RoT",J27*R27*S27,I27="A = L x H",J27*K27*L27,I27="A = CS",J27*O27,I27="A = A",J27*N27,I27="A = RoT",J27*R27*S27,I27="V = L x H x T",J27*K27*L27*M27,I27="V = L x CS",J27*K27*O27,I27="V = T x A",J27*M27*N27,I27="V = V",J27*P27,I27="V = RoT",J27*R27*S27,I27="M = M",J27*Q27,I27="M = RoT",J27*R27*S27,I27="","")} -> 8.19 | U27: {=_xlfn.IFNA(_xlfn.IFS($H27="length","m",$H27="area","m2",$H27="volume","m3",$H27="mass","kg",$H27="",""),"problem")} -> m3 | V27: Blocks bricks and precast products | W27: Solid brick | X27: Clay brick | Y27: Brick unit | AA27: {=_xlfn.IFNA(_xlfn.IFS($H27="Length",VLOOKUP($Y27,Densities,3,FALSE),$H27="area",VLOOKUP($Y27,Densities,4,FALSE),$H27="volume",VLOOKUP($Y27,Densities,5,FALSE),$H27="mass",1,$H27="",""),"enter density manually")} -> 1650 | AB27: {=_xlfn.IFNA(_xlfn.IFS($H27="length","kg/m",$H27="area","kg/m2",$H27="volume","kg/m3",$H27="mass","kg/kg",$H27="",""),"problem")} -> kg/m3 | AC27: =IF($T27="","",$T27*$AA27) -> 13513.5 | AD27: =IF($Y27="","",IFERROR(_xlfn.IFNA(IF($H27="volume",$AA27,VLOOKUP($Y27,Densities,5,FALSE)),"enter volumic density manually"),"enter volumic density manually")) -> 1650 | AE27: =IF($Y27="","",IF($AC27="","",$AC27/$AD27)) -> 8.19 | AF27: =_xlfn.IFNA(IF($Y27="","",VLOOKUP($Y27,_xlfn.CHOOSECOLS(Material_categories,4,9),2,FALSE)),"Assign material to its type in tab 'Matching of material categories'") -> Bricks and ceramics
B28: Steel portal roof beam | E28: Super | F28: Beams | G28: Structure | H28: Volume | I28: V = L x CS | J28: 8 | K28: 10 | O28: 0.02 | T28: {=_xlfn.IFS(I28="L = L",J28*K28,I28="L = RoT",J28*R28*S28,I28="A = L x H",J28*K28*L28,I28="A = CS",J28*O28,I28="A = A",J28*N28,I28="A = RoT",J28*R28*S28,I28="V = L x H x T",J28*K28*L28*M28,I28="V = L x CS",J28*K28*O28,I28="V = T x A",J28*M28*N28,I28="V = V",J28*P28,I28="V = RoT",J28*R28*S28,I28="M = M",J28*Q28,I28="M = RoT",J28*R28*S28,I28="","")} -> 1.6 | U28: {=_xlfn.IFNA(_xlfn.IFS($H28="length","m",$H28="area","m2",$H28="volume","m3",$H28="mass","kg",$H28="",""),"problem")} -> m3 | V28: Steel and metals | W28: Steel framing and reinforcement | X28: Steel sections | Y28: Section | AA28: {=_xlfn.IFNA(_xlfn.IFS($H28="Length",VLOOKUP($Y28,Densities,3,FALSE),$H28="area",VLOOKUP($Y28,Densities,4,FALSE),$H28="volume",VLOOKUP($Y28,Densities,5,FALSE),$H28="mass",1,$H28="",""),"enter density manually")} -> 7800 | AB28: {=_xlfn.IFNA(_xlfn.IFS($H28="length","kg/m",$H28="area","kg/m2",$H28="volume","kg/m3",$H28="mass","kg/kg",$H28="",""),"problem")} -> kg/m3 | AC28: =IF($T28="","",$T28*$AA28) -> 12480 | AD28: =IF($Y28="","",IFERROR(_xlfn.IFNA(IF($H28="volume",$AA28,VLOOKUP($Y28,Densities,5,FALSE)),"enter volumic density manually"),"enter volumic density manually")) -> 7800 | AE28: =IF($Y28="","",IF($AC28="","",$AC28/$AD28)) -> 1.6 | AF28: =_xlfn.IFNA(IF($Y28="","",VLOOKUP($Y28,_xlfn.CHOOSECOLS(Material_categories,4,9),2,FALSE)),"Assign material to its type in tab 'Matching of material categories'") -> Metal - steel
B29: Asbestos cement roofing | C29: Asbestos sheets | D29: Assumed thickness: 10mm | E29: Super | F29: Roof | G29: Skin | H29: Volume | I29: V = T x A | J29: 1 | M29: 0.01 | N29: 281.008 | T29: {=_xlfn.IFS(I29="L = L",J29*K29,I29="L = RoT",J29*R29*S29,I29="A = L x H",J29*K29*L29,I29="A = CS",J29*O29,I29="A = A",J29*N29,I29="A = RoT",J29*R29*S29,I29="V = L x H x T",J29*K29*L29*M29,I29="V = L x CS",J29*K29*O29,I29="V = T x A",J29*M29*N29,I29="V = V",J29*P29,I29="V = RoT",J29*R29*S29,I29="M = M",J29*Q29,I29="M = RoT",J29*R29*S29,I29="","")} -> 2.81008 | U29: {=_xlfn.IFNA(_xlfn.IFS($H29="length","m",$H29="area","m2",$H29="volume","m3",$H29="mass","kg",$H29="",""),"problem")} -> m3 | V29: Coverings claddings finishings | W29: Roofing | X29: Roof sheet flat | Y29: Asbestos sheet flat | AA29: {=_xlfn.IFNA(_xlfn.IFS($H29="Length",VLOOKUP($Y29,Densities,3,FALSE),$H29="area",VLOOKUP($Y29,Densities,4,FALSE),$H29="volume",VLOOKUP($Y29,Densities,5,FALSE),$H29="mass",1,$H29="",""),"enter density manually")} -> 17 | AB29: {=_xlfn.IFNA(_xlfn.IFS($H29="length","kg/m",$H29="area","kg/m2",$H29="volume","kg/m3",$H29="mass","kg/kg",$H29="",""),"problem")} -> kg/m3 | AC29: =IF($T29="","",$T29*$AA29) -> 47.77136 | AD29: =IF($Y29="","",IFERROR(_xlfn.IFNA(IF($H29="volume",$AA29,VLOOKUP($Y29,Densities,5,FALSE)),"enter volumic density manually"),"enter volumic density manually")) -> 17 | AE29: =IF($Y29="","",IF($AC29="","",$AC29/$AD29)) -> 2.81008 | AF29: =_xlfn.IFNA(IF($Y29="","",VLOOKUP($Y29,_xlfn.CHOOSECOLS(Material_categories,4,9),2,FALSE)),"Assign material to its type in tab 'Matching of material categories'") -> Others n.e.c
B30: Insulation quilt | C30: 50mm thick | D30: Information found in the description | E30: Super | F30: Roof | G30: Skin | H30: Volume | I30: V = T x A | J30: 1 | M30: 0.05 | N30: 281.008 | T30: {=_xlfn.IFS(I30="L = L",J30*K30,I30="L = RoT",J30*R30*S30,I30="A = L x H",J30*K30*L30,I30="A = CS",J30*O30,I30="A = A",J30*N30,I30="A = RoT",J30*R30*S30,I30="V = L x H x T",J30*K30*L30*M30,I30="V = L x CS",J30*K30*O30,I30="V = T x A",J30*M30*N30,I30="V = V",J30*P30,I30="V = RoT",J30*R30*S30,I30="M = M",J30*Q30,I30="M = RoT",J30*R30*S30,I30="","")} -> 14.0504 | U30: {=_xlfn.IFNA(_xlfn.IFS($H30="length","m",$H30="area","m2",$H30="volume","m3",$H30="mass","kg",$H30="",""),"problem")} -> m3 | V30: Insulation | W30: Board | X30: Mineral board insulation | Y30: Stonewool facade board | AA30: {=_xlfn.IFNA(_xlfn.IFS($H30="Length",VLOOKUP($Y30,Densities,3,FALSE),$H30="area",VLOOKUP($Y30,Densities,4,FALSE),$H30="volume",VLOOKUP($Y30,Densities,5,FALSE),$H30="mass",1,$H30="",""),"enter density manually")} -> 80 | AB30: {=_xlfn.IFNA(_xlfn.IFS($H30="length","kg/m",$H30="area","kg/m2",$H30="volume","kg/m3",$H30="mass","kg/kg",$H30="",""),"problem")} -> kg/m3 | AC30: =IF($T30="","",$T30*$AA30) -> 1124.032 | AD30: =IF($Y30="","",IFERROR(_xlfn.IFNA(IF($H30="volume",$AA30,VLOOKUP($Y30,Densities,5,FALSE)),"enter volumic density manually"),"enter volumic density manually")) -> 80 | AE30: =IF($Y30="","",IF($AC30="","",$AC30/$AD30)) -> 14.0504 | AF30: =_xlfn.IFNA(IF($Y30="","",VLOOKUP($Y30,_xlfn.CHOOSECOLS(Material_categories,4,9),2,FALSE)),"Assign material to its type in tab 'Matching of material categories'") -> Insulation wools
B31: Foil backed plastic faced plasterboard | C31: 9.5mm thick | D31: Information found in the description | E31: Super | F31: Roof | G31: Skin | H31: Volume | I31: V = T x A | J31: 1 | M31: 0.0095 | N31: 281.008 | T31: {=_xlfn.IFS(I31="L = L",J31*K31,I31="L = RoT",J31*R31*S31,I31="A = L x H",J31*K31*L31,I31="A = CS",J31*O31,I31="A = A",J31*N31,I31="A = RoT",J31*R31*S31,I31="V = L x H x T",J31*K31*L31*M31,I31="V = L x CS",J31*K31*O31,I31="V = T x A",J31*M31*N31,I31="V = V",J31*P31,I31="V = RoT",J31*R31*S31,I31="M = M",J31*Q31,I31="M = RoT",J31*R31*S31,I31="","")} -> 2.669576 | U31: {=_xlfn.IFNA(_xlfn.IFS($H31="length","m",$H31="area","m2",$H31="volume","m3",$H31="mass","kg",$H31="",""),"problem")} -> m3 | V31: Coverings claddings finishings | W31: Internal walls | X31: Plasterboard | Y31: Gypsum hardboard | AA31: {=_xlfn.IFNA(_xlfn.IFS($H31="Length",VLOOKUP($Y31,Densities,3,FALSE),$H31="area",VLOOKUP($Y31,Densities,4,FALSE),$H31="volume",VLOOKUP($Y31,Densities,5,FALSE),$H31="mass",1,$H31="",""),"enter density manually")} -> 930 | AB31: {=_xlfn.IFNA(_xlfn.IFS($H31="length","kg/m",$H31="area","kg/m2",$H31="volume","kg/m3",$H31="mass","kg/kg",$H31="",""),"problem")} -> kg/m3 | AC31: =IF($T31="","",$T31*$AA31) -> 2482.7057 | AD31: =IF($Y31="","",IFERROR(_xlfn.IFNA(IF($H31="volume",$AA31,VLOOKUP($Y31,Densities,5,FALSE)),"enter volumic density manually"),"enter volumic density manually")) -> 930 | AE31: =IF($Y31="","",IF($AC31="","",$AC31/$AD31)) -> 2.669576 | AF31: =_xlfn.IFNA(IF($Y31="","",VLOOKUP($Y31,_xlfn.CHOOSECOLS(Material_categories,4,9),2,FALSE)),"Assign material to its type in tab 'Matching of material categories'") -> Gypsum-based
